<?xml version="1.0" ?>
<mujoco model="robotnl">
    <!-- <compiler angle="radian" meshdir="assets"/> -->
    <compiler angle="radian" meshdir="assets" autolimits="true"/>
    <!-- <compiler angle="radian" autolimits="true"/> -->

    <default>
        <default class="robotnl">
        </default>
        <default class="visual">
            <geom type="mesh" contype="0" conaffinity="0" group="2"/>
        </default>
        <default class="collision">
            <geom group="3"/>
        </default>
    </default>

    <worldbody>
        <body name="base_link" pos="0 0 0.77" quat="1 0 0 0" childclass="robotnl">
            <freejoint name="base_freejoint"/>
            <!-- <camera name="robot_eye_view" pos="0 0.1 0.1" xyaxes="1 0 0 0 1 0" mode="fixed"/> -->
            <geom type="mesh" rgba="0.2 0.2 0.2 1" mesh="base_link" class="visual"/>
            <geom class="collision" type="box" pos="-0.0015 0 0.135" quat="1 0 0 0" size="0.094 0.159 0.13" friction="1.0 0.005 0.0001"/>
            <inertial pos="-0.0006059431640845468 -3.623569300705625e-05 0.10565029062737732" mass="12.024363374564382" fullinertia="0.130354 0.089122 0.096761 -0.0 0.000308 -2e-06" />
            <site group="3" name="imu" pos="0 0 0" quat="1 0 0 0"/>
            
            <body name="right_yaw_link" pos="-0.000141 -0.105033 0.00651">
                <inertial pos="-0.00339734 -1.77741e-07 -0.0448459" quat="0.510618 0.489152 0.489152 0.510618" mass="0.630571" diaginertia="0.004495 0.00380916 0.00101084" />
                <joint name="hip_yaw_right" pos="0 0 0" axis="0 0 1" limited="true" range="-1.5708 0.698132" frictionloss="0.1" armature="0.005" />
                <geom pos="0.000141 0.105033 -0.00651" type="mesh" rgba="0.85 0.85 0.85 1" mesh="right_yaw_link" class="visual"/>
                
                <body name="right_rp_link" pos="-0.09875 0 -0.095556">
                    <inertial pos="0.0964978 -0.00196216 7.7605e-05" quat="0.51785 0.495131 0.502531 0.483879" mass="3.30176" diaginertia="0.0125606 0.0120052 0.00455422" />
                    <joint name="hip_roll_right" pos="0 0 0" axis="1 0 0" limited="true" range="-1.5708 0.872665" frictionloss="0.1" armature="0.005" />
                    <geom pos="0.098891 0.105033 0.089046" type="mesh" rgba="0.65 0.65 0.65 1" mesh="right_rp_link" class="visual"/>
                    <geom class="collision" type="capsule" pos="0.1 0 0" quat="0.707107 0 0.707107 0" size="0.055 0.08" friction="1.0 0.005 0.0001"/>

                    <body name="right_upper_link" pos="0.1267 -0.0495 -4.3e-05">
                        <inertial pos="0.000489424 0.0521965 -0.148815" quat="0.999802 -0.015698 -0.0105326 0.00626974" mass="3.01188" diaginertia="0.0190704 0.0180601 0.0075185" />
                        <joint name="hip_pitch_right" pos="0 0 0" axis="0 1 0" limited="true" range="-1.8326 0.523599" frictionloss="0.1" armature="0.005" />
                        <geom pos="-0.027809 0.154533 0.089089" type="mesh" rgba="0.65 0.65 0.65 1" mesh="right_upper_link" class="visual"/>
                        <geom class="collision" type="sphere" pos="0 0.04 -0.3" size="0.07" friction="1.0 0.005 0.0001"/>
                        
                        <body name="right_lower_link" pos="0 -0.000539 -0.300001">
                            <inertial pos="0.000901001 0.0422133 -0.077147" quat="0.999817 -0.0189584 0.00220935 0.00151044" mass="2.19165" diaginertia="0.0203253 0.0187898 0.00361386" />
                            <joint name="knee_right" pos="0 0 0" axis="0 1 0" limited="true" range="0 2.1293" frictionloss="0.1" armature="0.005" />
                            <geom pos="-0.027809 0.155072 0.38909" type="mesh" rgba="0.85 0.85 0.85 1" mesh="right_lower_link" class="visual"/>
                            <geom class="collision" type="cylinder" pos="0 0.045 -0.2" quat="1 0 0 0" size="0.065 0.08" friction="1.0 0.005 0.0001"/>
                            <geom class="collision" type="cylinder" pos="0.045 0.11 -0.1" quat="1 0 0 0" size="0.005 0.1" friction="1.0 0.005 0.0001"/>

                            <body name="right_ankle_link" pos="0 0.071061 -0.299938">
                                <inertial pos="4.17137e-07 -0.0257499 3.35274e-05" quat="0 0.707107 0 0.707107" mass="0.0879064" diaginertia="5.4e-05 4.6e-05 1.3e-05" />
                                <joint name="ankle_pitch_right" pos="0 0 0" axis="0 1 0" limited="true" range="-1.22173 1.0472" frictionloss="0.1" armature="0.005" />
                                <geom pos="-0.027809 0.084011 0.689028" type="mesh" rgba="0.85 0.85 0.85 1" mesh="right_ankle_link" class="visual"/>

                                <body name="right_foot_link" pos="-0.044 -0.02575 -2.3e-05">
                                    <inertial pos="0.0579572 -0.000834115 -0.0518663" quat="-0.0110488 0.716462 0.0114637 0.697444" mass="0.797275" diaginertia="0.00229078 0.00180961 0.00121161" />
                                    <joint name="ankle_roll_right" pos="0 0 0" axis="1 0 0" limited="true" range="-0.523599 0.663225" frictionloss="0.1" armature="0.005" />
                                    <geom pos="0.016191 0.109761 0.689051" type="mesh" rgba="0.2 0.2 0.2 1" mesh="right_foot_link" class="visual"/>
                                    <geom class="collision" type="box" pos="0.068 -0.00035 -0.070" quat="1 0 0 0" size="0.1 0.065 0.0065" friction="1.0 0.005 0.0001"/>
                                </body>
                            </body>
                        </body>
                    </body>
                </body>
            </body>
            <body name="left_yaw_link" pos="-0.000141 0.104967 0.00651">
                <inertial pos="-0.00339734 -1.77741e-07 -0.0448447" quat="0.510618 0.489152 0.489152 0.510618" mass="0.630571" diaginertia="0.004495 0.00380916 0.00101084" />
                <joint name="hip_yaw_left" pos="0 0 0" axis="0 0 1" limited="true" range="-0.698132 1.5708" frictionloss="0.1" armature="0.005" />
                <geom pos="0.000141 -0.104967 -0.00651" type="mesh" rgba="0.85 0.85 0.85 1" mesh="left_yaw_link" class="visual"/>

                <body name="left_rp_link" pos="-0.09875 0 -0.095556">
                    <inertial pos="0.0964978 0.00196162 8.20493e-05" quat="0.482949 0.50342 0.494231 0.518715" mass="3.30176" diaginertia="0.0125607 0.012005 0.00455422" />
                    <joint name="hip_roll_left" pos="0 0 0" axis="1 0 0" limited="true" range="-0.698132 1.5708" frictionloss="0.1" armature="0.005" />
                    <geom pos="0.098891 -0.104967 0.089046" type="mesh" rgba="0.65 0.65 0.65 1" mesh="left_rp_link" class="visual"/>
                    <geom class="collision" type="capsule" pos="0.1 0 0" quat="0.707107 0 0.707107 0" size="0.055 0.08" friction="1.0 0.005 0.0001"/>
                    
                    <body name="left_upper_link" pos="0.1267 0.0495 6.9e-05">
                        <inertial pos="0.000485381 -0.0512031 -0.14895" quat="0.999779 0.0168625 -0.010792 -0.00635802" mass="3.1934" diaginertia="0.0191216 0.0181047 0.00757566" />
                        <joint name="hip_pitch_left" pos="0 0 0" axis="0 1 0" limited="true" range="-1.8326 0.523599" frictionloss="0.1" armature="0.005" />
                        <geom pos="-0.027809 -0.154467 0.088977" type="mesh" rgba="0.65 0.65 0.65 1" mesh="left_upper_link" class="visual"/>
                        <geom class="collision" type="sphere" pos="0 -0.04 -0.3" size="0.07" friction="1.0 0.005 0.0001"/>

                        <body name="left_lower_link" pos="0 0.008219 -0.299989">
                            <inertial pos="0.000936268 -0.0488579 -0.0771858" quat="0.999793 0.0202114 0.00228081 -0.000303885" mass="2.18988" diaginertia="0.0203273 0.0187938 0.00361386" />
                            <joint name="knee_left" pos="0 0 0" axis="0 1 0" limited="true" range="0 2.1293" frictionloss="0.1" armature="0.005" />
                            <geom pos="-0.027809 -0.162686 0.388966" type="mesh" rgba="0.85 0.85 0.85 1" mesh="left_lower_link" class="visual"/>
                            <geom class="collision" type="cylinder" pos="0 -0.05 -0.2" quat="1 0 0 0" size="0.065 0.08" friction="1.0 0.005 0.0001"/>
                            <geom class="collision" type="cylinder" pos="0.045 -0.115 -0.1" quat="1 0 0 0" size="0.005 0.1" friction="1.0 0.005 0.0001"/>

                            <body name="left_ankle_link" pos="0 -0.025581 -0.300036">
                                <inertial pos="-1.28793e-06 -0.0257501 2.02299e-05" quat="0 0.707107 0 0.707107" mass="0.0879065" diaginertia="5.4e-05 4.6e-05 1.3e-05" />
                                <joint name="ankle_pitch_left" pos="0 0 0" axis="0 1 0" limited="true" range="-1.22173 1.0472" frictionloss="0.1" armature="0.005" />
                                <geom pos="-0.027809 -0.137105 0.689002" type="mesh" rgba="0.85 0.85 0.85 1" mesh="left_ankle_link" class="visual"/>
                                
                                <body name="left_foot_link" pos="-0.044 -0.02575 -3.6e-05">
                                    <inertial pos="0.0623584 0.000911997 -0.0518651" quat="0.0103193 0.71646 -0.0122071 0.697445" mass="0.797275" diaginertia="0.00229078 0.0018106 0.00121161" />
                                    <joint name="ankle_roll_left" pos="0 0 0" axis="1 0 0" limited="true" range="-0.663225 0.523599" frictionloss="0.1" armature="0.005" />
                                    <geom pos="0.016191 -0.111355 0.689038" type="mesh" rgba="0.2 0.2 0.2 1" mesh="left_foot_link" class="visual"/>
                                    <geom class="collision" type="box" pos="0.0725 0.0005 -0.07" quat="1 0 0 0" size="0.1 0.065 0.0065" friction="1.0 0.005 0.0001"/>
                                </body>
                            </body>
                        </body>
                    </body>
                </body>
            </body>
        </body>
    </worldbody>

    <asset>
        <mesh name="base_link"          file="robotnl_meshes/base_link.stl"            scale="0.001 0.001 0.001" />
        <mesh name="right_yaw_link"     file="robotnl_meshes/right_yaw.stl"            scale="0.001 0.001 0.001" />
        <mesh name="right_rp_link"      file="robotnl_meshes/right_rp.stl"             scale="0.001 0.001 0.001" />
        <mesh name="right_upper_link"   file="robotnl_meshes/right_upper_link.stl"     scale="0.001 0.001 0.001" />
        <mesh name="right_lower_link"   file="robotnl_meshes/right_lower_link.stl"     scale="0.001 0.001 0.001" />
        <mesh name="right_ankle_link"   file="robotnl_meshes/right_ankle.stl"          scale="0.001 0.001 0.001" />
        <mesh name="right_foot_link"    file="robotnl_meshes/right_foot.stl"           scale="0.001 0.001 0.001" />
        <mesh name="left_yaw_link"      file="robotnl_meshes/left_yaw.stl"             scale="0.001 0.001 0.001" />
        <mesh name="left_rp_link"       file="robotnl_meshes/left_rp.stl"              scale="0.001 0.001 0.001" />
        <mesh name="left_upper_link"    file="robotnl_meshes/left_upper_link.stl"      scale="0.001 0.001 0.001" />
        <mesh name="left_lower_link"    file="robotnl_meshes/left_lower_link.stl"      scale="0.001 0.001 0.001" />
        <mesh name="left_ankle_link"    file="robotnl_meshes/left_ankle.stl"           scale="0.001 0.001 0.001" />
        <mesh name="left_foot_link"     file="robotnl_meshes/left_foot.stl"            scale="0.001 0.001 0.001" />
    </asset>

    <actuator>
        <motor name="hip_yaw_left"          joint="hip_yaw_left"          forcerange="-40 40"/>
        <motor name="hip_yaw_right"         joint="hip_yaw_right"         forcerange="-40 40"/>
        <motor name="hip_roll_left"         joint="hip_roll_left"         forcerange="-40 40"/>
        <motor name="hip_roll_right"        joint="hip_roll_right"        forcerange="-40 40"/>
        <motor name="hip_pitch_left"        joint="hip_pitch_left"        forcerange="-60 60"/>
        <motor name="hip_pitch_right"       joint="hip_pitch_right"       forcerange="-60 60"/>
        <motor name="knee_left"             joint="knee_left"             forcerange="-60 60"/>
        <motor name="knee_right"            joint="knee_right"            forcerange="-60 60"/>
        <motor name="ankle_pitch_left"      joint="ankle_pitch_left"      forcerange="-6  6 "/>
        <motor name="ankle_pitch_right"     joint="ankle_pitch_right"     forcerange="-6  6 "/>
        <motor name="ankle_roll_left"       joint="ankle_roll_left"       forcerange="-6  6 "/>
        <motor name="ankle_roll_right"      joint="ankle_roll_right"      forcerange="-6  6 "/>        
    </actuator>

    <sensor>
        <jointpos name="hip_yaw_left_pos"          joint="hip_yaw_left"       />
        <jointpos name="hip_yaw_right_pos"         joint="hip_yaw_right"      />
        <jointpos name="hip_roll_left_pos"         joint="hip_roll_left"      />
        <jointpos name="hip_roll_right_pos"        joint="hip_roll_right"     />
        <jointpos name="hip_pitch_left_pos"        joint="hip_pitch_left"     />
        <jointpos name="hip_pitch_right_pos"       joint="hip_pitch_right"    />
        <jointpos name="knee_left_pos"             joint="knee_left"          />
        <jointpos name="knee_right_pos"            joint="knee_right"         />
        <jointpos name="ankle_pitch_left_pos"      joint="ankle_pitch_left"   />
        <jointpos name="ankle_pitch_right_pos"     joint="ankle_pitch_right"  />
        <jointpos name="ankle_roll_left_pos"       joint="ankle_roll_left"    />
        <jointpos name="ankle_roll_right_pos"      joint="ankle_roll_right"   />
        

        <jointvel name="hip_yaw_left_vel"          joint="hip_yaw_left"       />
        <jointvel name="hip_yaw_right_vel"         joint="hip_yaw_right"      />
        <jointvel name="hip_roll_left_vel"         joint="hip_roll_left"      />
        <jointvel name="hip_roll_right_vel"        joint="hip_roll_right"     />
        <jointvel name="hip_pitch_left_vel"        joint="hip_pitch_left"     />
        <jointvel name="hip_pitch_right_vel"       joint="hip_pitch_right"    />
        <jointvel name="knee_left_vel"             joint="knee_left"          />
        <jointvel name="knee_right_vel"            joint="knee_right"         />
        <jointvel name="ankle_pitch_left_vel"      joint="ankle_pitch_left"   />
        <jointvel name="ankle_pitch_right_vel"     joint="ankle_pitch_right"  />
        <jointvel name="ankle_roll_left_vel"       joint="ankle_roll_left"    />
        <jointvel name="ankle_roll_right_vel"      joint="ankle_roll_right"   />
        

        <jointactuatorfrc name="hip_yaw_left_torque"          joint="hip_yaw_left"       />
        <jointactuatorfrc name="hip_yaw_right_torque"         joint="hip_yaw_right"      />
        <jointactuatorfrc name="hip_roll_left_torque"         joint="hip_roll_left"      />
        <jointactuatorfrc name="hip_roll_right_torque"        joint="hip_roll_right"     />
        <jointactuatorfrc name="hip_pitch_left_torque"        joint="hip_pitch_left"     />
        <jointactuatorfrc name="hip_pitch_right_torque"       joint="hip_pitch_right"    />
        <jointactuatorfrc name="knee_left_torque"             joint="knee_left"          />
        <jointactuatorfrc name="knee_right_torque"            joint="knee_right"         />
        <jointactuatorfrc name="ankle_pitch_left_torque"      joint="ankle_pitch_left"   />
        <jointactuatorfrc name="ankle_pitch_right_torque"     joint="ankle_pitch_right"  />
        <jointactuatorfrc name="ankle_roll_left_torque"       joint="ankle_roll_left"    />
        <jointactuatorfrc name="ankle_roll_right_torque"      joint="ankle_roll_right"   />        

        <framequat name="imu_quat" objtype="site" objname="imu" />
        <gyro name="imu_gyro" site="imu" />
        <accelerometer name="imu_acc" site="imu" />
        <framepos name="frame_pos" objtype="site" objname="imu" />
        <framelinvel name="frame_vel" objtype="site" objname="imu" />
    </sensor>
    <equality/>

    <statistic center="0 0 0.1" extent="0.8"/>
    <visual>
        <headlight diffuse="0.6 0.6 0.6" ambient="0.3 0.3 0.3" specular="0 0 0"/>
        <rgba haze="0.15 0.25 0.35 1"/>
        <global azimuth="120" elevation="-20"/>
    </visual>
    <asset>
        <texture type="skybox" builtin="gradient" rgb1="0.3 0.5 0.7" rgb2="0 0 0" width="512" height="3072"/>
        <texture type="2d" name="groundplane" builtin="checker" mark="edge" rgb1="0.2 0.3 0.4" rgb2="0.1 0.2 0.3"
        markrgb="0.8 0.8 0.8" width="300" height="300"/>
        <material name="groundplane" texture="groundplane" texuniform="true" texrepeat="5 5" reflectance="0.2"/>
    </asset>
    <worldbody>
        <light pos="0 0 1.5" dir="0 0 -1" directional="true"/>
        <geom name="floor" size="0 0 0.05" type="plane" material="groundplane" friction="1.0 0.005 0.0001"/>
    </worldbody>

</mujoco>
