<?xml version="1.0" ?>
<robot name="total_robot_nl" xmlns:xacro="http://www.ros.org/wiki/xacro">

<link name = "world"/>
<link name = "base_link"/>
<link name = "pitch"/>
<link name="pelvis">
  <inertial>
    <origin xyz="-0.00020305658642525651 -2.299524657931652e-06 0.1172286439789711" rpy="0 0 0"/>
    <mass value="5.152280783786209"/>
    <inertia ixx="0.047442" iyy="0.033846" izz="0.037155" ixy="-0.0" iyz="-1e-06" ixz="0.000292"/>
  </inertial>
  <visual>
    <origin xyz="0 0 0" rpy="0 0 0"/>
    <geometry>
      <mesh filename="package://ik_test/meshes/meshes/base_link.stl" scale="0.001 0.001 0.001"/>
    </geometry>
    <material name="silver">
      <color rgba="0.85 0.85 0.85 1.000"/>
    </material>
  </visual>
  <collision>
    <origin xyz="0 0 0" rpy="0 0 0"/>
    <geometry>
      <mesh filename="package://ik_test/meshes/meshes/base_link.stl" scale="0.001 0.001 0.001"/>
    </geometry>
  </collision>
</link>

<link name="right_yaw">
  <inertial>
    <origin xyz="-0.003387170114723884 3.4379261523720395e-07 -0.044730635776334654" rpy="0 0 0"/>
    <mass value="0.23424145827439846"/>
    <inertia ixx="0.000378" iyy="0.001666" izz="0.001409" ixy="0.0" iyz="0.0" ixz="-4.5e-05"/>
  </inertial>
  <visual>
    <origin xyz="0.001536 0.105 -0.006958" rpy="0 0 0"/>
    <geometry>
      <mesh filename="package://ik_test/meshes/meshes/right_yaw.stl" scale="0.001 0.001 0.001"/>
    </geometry>
    <material name="silver">
      <color rgba="0.85 0.85 0.85 1.000"/>
    </material>
  </visual>
  <collision>
    <origin xyz="0.001536 0.105 -0.006958" rpy="0 0 0"/>
    <geometry>
      <mesh filename="package://ik_test/meshes/meshes/right_yaw.stl" scale="0.001 0.001 0.001"/>
    </geometry>
  </collision>
</link>

<link name="right_rp">
  <inertial>
    <origin xyz="0.003062145 -0.002214028202584803 -6.154780610961863e-05" rpy="0 0 0"/>
    <mass value="0.690812556297437"/>
    <inertia ixx="0.00118" iyy="0.00287" izz="0.00271" ixy="4.3e-05" iyz="-6e-06" ixz="-4e-06"/>
  </inertial>
  <visual>
    <origin xyz="0.001536 0.105 0.088598" rpy="0 0 0"/>
    <geometry>
      <mesh filename="package://ik_test/meshes/meshes/right_rp.stl" scale="0.001 0.001 0.001"/>
    </geometry>
    <material name="silver">
      <color rgba="0.85 0.85 0.85 1.000"/>
    </material>
  </visual>
  <collision>
    <origin xyz="0.001536 0.105 0.088598" rpy="0 0 0"/>
    <geometry>
      <mesh filename="package://ik_test/meshes/meshes/right_rp.stl" scale="0.001 0.001 0.001"/>
    </geometry>
  </collision>
</link>

<link name="right_upper_link">
  <inertial>
    <origin xyz="0.002301542175954175 -0.002972894 -0.15079668153621606" rpy="0 0 0"/>
    <mass value="0.9258424873332725"/>
    <inertia ixx="0.006961" iyy="0.006745" izz="0.002544" ixy="7e-06" iyz="-0.000146" ixz="0.000217"/>
  </inertial>
  <visual>
    <origin xyz="-0.026414 0.105 0.088641" rpy="0 0 0"/>
    <geometry>
      <mesh filename="package://ik_test/meshes/meshes/right_upper_link.stl" scale="0.001 0.001 0.001"/>
    </geometry>
    <material name="silver">
      <color rgba="0.85 0.85 0.85 1.000"/>
    </material>
  </visual>
  <collision>
    <origin xyz="-0.026414 0.105 0.088641" rpy="0 0 0"/>
    <geometry>
      <mesh filename="package://ik_test/meshes/meshes/right_upper_link.stl" scale="0.001 0.001 0.001"/>
    </geometry>
  </collision>
</link>

<link name="right_lower_link">
  <inertial>
    <origin xyz="0.001498001214367918 -0.002773083 -0.08163965093235381" rpy="0 0 0"/>
    <mass value="0.6817251658718579"/>
    <inertia ixx="0.007024" iyy="0.006492" izz="0.001195" ixy="-0.0" iyz="-4.5e-05" ixz="-5.2e-05"/>
  </inertial>
  <visual>
    <origin xyz="-0.026414 0.110288 0.388641" rpy="0 0 0"/>
    <geometry>
      <mesh filename="package://ik_test/meshes/meshes/right_lower_link.stl" scale="0.001 0.001 0.001"/>
    </geometry>
    <material name="silver">
      <color rgba="0.85 0.85 0.85 1.000"/>
    </material>
  </visual>
  <collision>
    <origin xyz="-0.026414 0.110288 0.388641" rpy="0 0 0"/>
    <geometry>
      <mesh filename="package://ik_test/meshes/meshes/right_lower_link.stl" scale="0.001 0.001 0.001"/>
    </geometry>
  </collision>
</link>

<link name="right_ankle">
  <inertial>
    <origin xyz="4.824912801307257e-07 -0.000000367 3.398427368073165e-05" rpy="0 0 0"/>
    <mass value="0.03255793420333914"/>
    <inertia ixx="5e-06" iyy="1.7e-05" izz="2e-05" ixy="-0.0" iyz="-0.0" ixz="0.0"/>
  </inertial>
  <visual>
    <origin xyz="-0.026414 0.109727 0.68858" rpy="0 0 0"/>
    <geometry>
      <mesh filename="package://ik_test/meshes/meshes/right_ankle.stl" scale="0.001 0.001 0.001"/>
    </geometry>
    <material name="silver">
      <color rgba="0.85 0.85 0.85 1.000"/>
    </material>
  </visual>
  <collision>
    <origin xyz="-0.026414 0.109727 0.68858" rpy="0 0 0"/>
    <geometry>
      <mesh filename="package://ik_test/meshes/meshes/right_ankle.stl" scale="0.001 0.001 0.001"/>
    </geometry>
  </collision>
</link>

<link name="right_foot">
  <inertial>
    <origin xyz="0.01761519535511249 -0.0005768277267058086 -0.0580822077884815" rpy="0 0 0"/>
    <mass value="0.4255598361250292"/>
    <inertia ixx="0.000686" iyy="0.001174" izz="0.001512" ixy="-8e-06" iyz="2e-06" ixz="3.2e-05"/>
  </inertial>
  <visual>
    <origin xyz="-0.026414 0.109727 0.688602" rpy="0 0 0"/>
    <geometry>
      <mesh filename="package://ik_test/meshes/meshes/right_foot.stl" scale="0.001 0.001 0.001"/>
    </geometry>
    <material name="silver">
      <color rgba="0.85 0.85 0.85 1.000"/>
    </material>
  </visual>
  <collision>
    <origin xyz="-0.026414 0.109727 0.688602" rpy="0 0 0"/>
    <geometry>
      <mesh filename="package://ik_test/meshes/meshes/right_foot.stl" scale="0.001 0.001 0.001"/>
    </geometry>
  </collision>
</link>

<link name="left_yaw">
  <inertial>
    <origin xyz="-0.003387170113489349 3.437926530541757e-07 -0.04472797689299879" rpy="0 0 0"/>
    <mass value="0.23424145827233966"/>
    <inertia ixx="0.000378" iyy="0.001666" izz="0.001409" ixy="0.0" iyz="-0.0" ixz="-4.5e-05"/>
  </inertial>
  <visual>
    <origin xyz="0.001536 -0.105 -0.006958" rpy="0 0 0"/>
    <geometry>
      <mesh filename="package://ik_test/meshes/meshes/left_yaw.stl" scale="0.001 0.001 0.001"/>
    </geometry>
    <material name="silver">
      <color rgba="0.85 0.85 0.85 1.000"/>
    </material>
  </visual>
  <collision>
    <origin xyz="0.001536 -0.105 -0.006958" rpy="0 0 0"/>
    <geometry>
      <mesh filename="package://ik_test/meshes/meshes/left_yaw.stl" scale="0.001 0.001 0.001"/>
    </geometry>
  </collision>
</link>

<link name="left_rp">
  <inertial>
    <origin xyz="0.003062159 0.002214840752492689 -5.654296421113425e-05" rpy="0 0 0"/>
    <mass value="0.6908122901011517"/>
    <inertia ixx="0.00118" iyy="0.002869" izz="0.00271" ixy="-4.3e-05" iyz="7e-06" ixz="-4e-06"/>
  </inertial>
  <visual>
    <origin xyz="0.001536 -0.105 0.088598" rpy="0 0 0"/>
    <geometry>
      <mesh filename="package://ik_test/meshes/meshes/left_rp.stl" scale="0.001 0.001 0.001"/>
    </geometry>
    <material name="silver">
      <color rgba="0.85 0.85 0.85 1.000"/>
    </material>
  </visual>
  <collision>
    <origin xyz="0.001536 -0.105 0.088598" rpy="0 0 0"/>
    <geometry>
      <mesh filename="package://ik_test/meshes/meshes/left_rp.stl" scale="0.001 0.001 0.001"/>
    </geometry>
  </collision>
</link>

<link name="left_upper_link">
  <inertial>
    <origin xyz="0.0023146429745539224 0.003311485 -0.1508794685104973" rpy="0 0 0"/>
    <mass value="0.9255380783714433"/>
    <inertia ixx="0.006959" iyy="0.006742" izz="0.002543" ixy="-8e-06" iyz="0.000155" ixz="0.000218"/>
  </inertial>
  <visual>
    <origin xyz="-0.026414 -0.105 0.088529" rpy="0 0 0"/>
    <geometry>
      <mesh filename="package://ik_test/meshes/meshes/left_upper_link.stl" scale="0.001 0.001 0.001"/>
    </geometry>
    <material name="silver">
      <color rgba="0.85 0.85 0.85 1.000"/>
    </material>
  </visual>
  <collision>
    <origin xyz="-0.026414 -0.105 0.088529" rpy="0 0 0"/>
    <geometry>
      <mesh filename="package://ik_test/meshes/meshes/left_upper_link.stl" scale="0.001 0.001 0.001"/>
    </geometry>
  </collision>
</link>

<link name="left_lower_link">
  <inertial>
    <origin xyz="0.0014979772223235738 0.00325822 -0.08174396151435326" rpy="0 0 0"/>
    <mass value="0.6817257546564137"/>
    <inertia ixx="0.007024" iyy="0.006492" izz="0.001195" ixy="0.0" iyz="5.7e-05" ixz="-5.2e-05"/>
  </inertial>
  <visual>
    <origin xyz="-0.026414 -0.110969 0.388517" rpy="0 0 0"/>
    <geometry>
      <mesh filename="package://ik_test/meshes/meshes/left_lower_link.stl" scale="0.001 0.001 0.001"/>
    </geometry>
    <material name="silver">
      <color rgba="0.85 0.85 0.85 1.000"/>
    </material>
  </visual>
  <collision>
    <origin xyz="-0.026414 -0.110969 0.388517" rpy="0 0 0"/>
    <geometry>
      <mesh filename="package://ik_test/meshes/meshes/left_lower_link.stl" scale="0.001 0.001 0.001"/>
    </geometry>
  </collision>
</link>

<link name="left_ankle">
  <inertial>
    <origin xyz="-1.2225763775797205e-06 0.000000402 1.968676151820059e-05" rpy="0 0 0"/>
    <mass value="0.032557947198084525"/>
    <inertia ixx="5e-06" iyy="1.7e-05" izz="2e-05" ixy="0.0" iyz="-0.0" ixz="-0.0"/>
  </inertial>
  <visual>
    <origin xyz="-0.026414 -0.111388 0.688553" rpy="0 0 0"/>
    <geometry>
      <mesh filename="package://ik_test/meshes/meshes/left_ankle.stl" scale="0.001 0.001 0.001"/>
    </geometry>
    <material name="silver">
      <color rgba="0.85 0.85 0.85 1.000"/>
    </material>
  </visual>
  <collision>
    <origin xyz="-0.026414 -0.111388 0.688553" rpy="0 0 0"/>
    <geometry>
      <mesh filename="package://ik_test/meshes/meshes/left_ankle.stl" scale="0.001 0.001 0.001"/>
    </geometry>
  </collision>
</link>

<link name="left_foot">
  <inertial>
    <origin xyz="0.02701606411021572 0.0006641852928514075 -0.058081445541025456" rpy="0 0 0"/>
    <mass value="0.42555979909734665"/>
    <inertia ixx="0.000686" iyy="0.001174" izz="0.001512" ixy="8e-06" iyz="-2e-06" ixz="3.2e-05"/>
  </inertial>
  <visual>
    <origin xyz="-0.031414 -0.111388 0.688589" rpy="0 0 0"/>
    <geometry>
      <mesh filename="package://ik_test/meshes/meshes/left_foot.stl" scale="0.001 0.001 0.001"/>
    </geometry>
    <material name="silver">
      <color rgba="0.85 0.85 0.85 1.000"/>
    </material>
  </visual>
  <collision>
    <origin xyz="-0.031414 -0.111388 0.688589" rpy="0 0 0"/>
    <geometry>
      <mesh filename="package://ik_test/meshes/meshes/left_foot.stl" scale="0.001 0.001 0.001"/>
    </geometry>
  </collision>
</link>


<joint name="pel_roll" type="revolute">
  <origin xyz="0 0 0" rpy="0 0 0"/>
  <parent link="world"/>
  <child link="base_link"/>
  <axis xyz="1 0 0"/>
  <limit upper="3.141592" lower="-3.141592" effort="100" velocity="100"/>
</joint>

<joint name="pel_pitch" type="revolute">
  <origin xyz="0 0 0" rpy="0 0 0"/>
  <parent link="base_link"/>
  <child link="pitch"/>
  <axis xyz="0 1 0"/>
  <limit upper="3.141592" lower="-3.141592" effort="100" velocity="100"/>
</joint>

<joint name="pel_yaw" type="revolute">
  <origin xyz="0.0041825 0 -0.31746" rpy="0 0 0"/>
  <parent link="pitch"/>
  <child link="pelvis"/>
  <axis xyz="0 0 1"/>
  <limit upper="3.141592" lower="-3.141592" effort="100" velocity="100"/>
</joint>

<joint name="hip_yaw_right" type="revolute">
  <origin xyz="-0.001536 -0.105 0.006958" rpy="0 0 0"/>
  <parent link="pelvis"/>
  <child link="right_yaw"/>
  <axis xyz="0.0 0.0 1.0"/>
  <limit upper="1.570796" lower="-0.698132" effort="100" velocity="100"/>
</joint>

<joint name="hip_roll_right" type="revolute">
  <origin xyz="0.0 0.0 -0.095556" rpy="0 0 0"/>
  <parent link="right_yaw"/>
  <child link="right_rp"/>
  <axis xyz="1.0 0.0 0.0"/>
  <limit upper="0.872665" lower="-1.570796" effort="100" velocity="100"/>
</joint>

<joint name="hip_pitch_right" type="revolute">
  <origin xyz="0.02795 0.0 0.0" rpy="0 0 0"/>
  <parent link="right_rp"/>
  <child link="right_upper_link"/>
  <axis xyz="0.0 1.0 0.0"/>
  <limit upper="1.832596" lower="-0.523599" effort="100" velocity="100"/>
</joint>

<joint name="knee_right" type="revolute">
  <origin xyz="0.0 -0.005288 -0.3" rpy="0 0 0"/>
  <parent link="right_upper_link"/>
  <child link="right_lower_link"/>
  <axis xyz="0.0 1.0 0.0"/>
  <limit upper="0.0" lower="-2.129302" effort="100" velocity="100"/>
</joint>

<joint name="ankle_pitch_right" type="revolute">
  <origin xyz="0.0 0.000561 -0.3" rpy="0 0 0"/>
  <parent link="right_lower_link"/>
  <child link="right_ankle"/>
  <axis xyz="0.0 1.0 0.0"/>
  <limit upper="1.22173" lower="-1.047198" effort="100" velocity="100"/>
</joint>

<joint name="ankle_roll_right" type="revolute">
  <origin xyz="0.0 0.0 0.0" rpy="0 0 0"/>
  <parent link="right_ankle"/>
  <child link="right_foot"/>
  <axis xyz="1.0 0.0 0.0"/>
  <limit upper="0.663225" lower="-0.523599" effort="100" velocity="100"/>
</joint>

<joint name="hip_yaw_left" type="revolute">
  <origin xyz="-0.001536 0.105 0.006958" rpy="0 0 0"/>
  <parent link="pelvis"/>
  <child link="left_yaw"/>
  <axis xyz="0.0 0.0 1.0"/>
  <limit upper="0.698132" lower="-1.570796" effort="100" velocity="100"/>
</joint>

<joint name="hip_roll_left" type="revolute">
  <origin xyz="0.0 0.0 -0.095556" rpy="0 0 0"/>
  <parent link="left_yaw"/>
  <child link="left_rp"/>
  <axis xyz="1.0 0.0 0.0"/>
  <limit upper="0.698132" lower="-1.570796" effort="100" velocity="100"/>
</joint>

<joint name="hip_pitch_left" type="revolute">
  <origin xyz="0.02795 0.0 0.0" rpy="0 0 0"/>
  <parent link="left_rp"/>
  <child link="left_upper_link"/>
  <axis xyz="0.0 1 0.0"/>
  <limit upper="1.832596" lower="-0.523599" effort="100" velocity="100"/>
</joint>

<joint name="knee_left" type="revolute">
  <origin xyz="0.0 0.005969 -0.3" rpy="0 0 0"/>
  <parent link="left_upper_link"/>
  <child link="left_lower_link"/>
  <axis xyz="0.0 1.0 0.0"/>
  <limit upper="0.0" lower="-2.129302" effort="100" velocity="100"/>
</joint>

<joint name="ankle_pitch_left" type="revolute">
  <origin xyz="0.0 0.000419 -0.3" rpy="0 0 0"/>
  <parent link="left_lower_link"/>
  <child link="left_ankle"/>
  <axis xyz="0.0 1.0 0.0"/>
  <limit upper="1.22173" lower="-1.047198" effort="100" velocity="100"/>
</joint>

<joint name="ankle_roll_left" type="revolute">
  <origin xyz="0.0 0.0 0.0" rpy="0 0 0"/>
  <parent link="left_ankle"/>
  <child link="left_foot"/>
  <axis xyz="1.0 0.0 0.0"/>
  <limit upper="0.663225" lower="-0.523599" effort="100" velocity="100"/>
</joint>

</robot>
