<?xml version="1.0" ?>
<robot name="total_robot_nl" xmlns:xacro="http://www.ros.org/wiki/xacro">
<!-- 
<link name = "base_link">
  <inertial>
    <origin xyz="0 0 0" rpy="0 0 0"/>
    <mass value="0"/>
    <inertia ixx="0" iyy="0" izz="0" ixy="0" iyz="0" ixz="0"/>
  </inertial>
  <visual>
    <origin xyz="0 0 0" rpy="0 0 0"/>
    <geometry>
      <box size="0.01 0.01 0.01"/>
    </geometry>
  </visual>
</link> -->
<link name="world"/>
  
<link name="base_link">
  <inertial>
    <origin xyz="-0.0032551439878857943 -1.9999997873110242e-07 -0.04529620573945425" rpy="0 0 0"/>
    <mass value="0.6322493948478245"/>
    <inertia ixx="0.001017" iyy="0.004505" izz="0.003813" ixy="-0.0" iyz="-0.0" ixz="-0.000121"/>
  </inertial>
  <visual>
    <origin xyz="0.015291 -0.105 -0.007699" rpy="0 0 0"/>
    <geometry>
      <mesh filename="package://ik_test/meshes/left_yaw_1_1_1.stl" scale="0.001 0.001 0.001"/>
    </geometry>
    <material name="silver">
      <color rgba="0.700 0.700 0.700 1.000"/>
    </material>
  </visual>
</link>

<link name="left_hip_rp_1_1_1">
  <!-- <inertial>
    <origin xyz="0.197224872 0.0019294190715901938 9.221403702634745e-05" rpy="0 0 0"/>
    <mass value="3.4935634589938322"/>
    <inertia ixx="0.004865" iyy="0.013016" izz="0.012468" ixy="-0.000209" iyz="2.4e-05" ixz="-3.8e-05"/>
  </inertial> -->
  <inertial>
    <origin xyz="-0.000275128 0.0019294190715901938 9.221403702634745e-05" rpy="0 0 0"/>
    <mass value="3.4935634589938322"/>
    <inertia ixx="0.004865" iyy="0.013016" izz="0.012468" ixy="-0.000209" iyz="2.4e-05" ixz="-3.8e-05"/>
  </inertial>
  <visual>
    <origin xyz="0.015291 -0.105 0.088357" rpy="0 0 0"/>
    <geometry>
      <mesh filename="package://ik_test/meshes/left_hip_rp_1_1_1.stl" scale="0.001 0.001 0.001"/>
    </geometry>
    <material name="silver">
      <color rgba="0.700 0.700 0.700 1.000"/>
    </material>
  </visual>
</link>

<link name="left_upper_link_1_1_1">
  <inertial>
    <origin xyz="0.0005368519739045955 -0.013754235 -0.15022534580925995" rpy="0 0 0"/>
    <mass value="3.2234265717066637"/>
    <inertia ixx="0.017939" iyy="0.016979" izz="0.00754" ixy="-2.3e-05" iyz="0.000318" ixz="0.000252"/>
  </inertial>
  <visual>
    <origin xyz="-0.012959 -0.11025 0.088358" rpy="0 0 0"/>
    <geometry>
      <mesh filename="package://ik_test/meshes/left_upper_link_1_1_1.stl" scale="0.001 0.001 0.001"/>
    </geometry>
    <material name="silver">
      <color rgba="0.700 0.700 0.700 1.000"/>
    </material>
  </visual>
  <collision>
    <geometry>
      <sphere radius="0.06"/> 
    </geometry>
    <origin xyz="0 0.00075 -0.3" rpy="0 0 0"/>
  </collision>
</link>

<link name="left_lower_link_1_1_1">
  <inertial>
    <origin xyz="4.6165273849790855e-05 0.006328049 -0.07736569907214441" rpy="0 0 0"/>
    <mass value="2.17378151180509"/>
    <inertia ixx="0.020231" iyy="0.018702" izz="0.003549" ixy="-3e-06" iyz="0.000559" ixz="-3.7e-05"/>
  </inertial>
  <visual>
    <origin xyz="-0.012959 -0.106762 0.388359" rpy="0 0 0"/>
    <geometry>
      <mesh filename="package://ik_test/meshes/left_lower_link_1_1_1.stl" scale="0.001 0.001 0.001"/>
    </geometry>
    <material name="silver">
      <color rgba="0.700 0.700 0.700 1.000"/>
    </material>
  </visual>
</link>

<link name="left_ankle_1_1_1">
  <inertial>
    <origin xyz="-5.379963106347946e-07 -0.000000102 2.7555327962835996e-05" rpy="0 0 0"/>
    <mass value="0.09508662408365151"/>
    <inertia ixx="1.3e-05" iyy="6.1e-05" izz="6.9e-05" ixy="-0.0" iyz="0.0" ixz="0.0"/>
  </inertial>
  <visual>
    <origin xyz="-0.012959 -0.110275 0.688358" rpy="0 0 0"/>
    <geometry>
      <mesh filename="package://ik_test/meshes/left_ankle_1_1_1.stl" scale="0.001 0.001 0.001"/>
    </geometry>
    <material name="silver">
      <color rgba="0.700 0.700 0.700 1.000"/>
    </material>
  </visual>
</link>

<link name="left_foot_1_1_1">
  <inertial>
    <origin xyz="0.005144916 0.001279712439850464 -0.05369204517562853" rpy="0 0 0"/>
    <mass value="0.7654264928180347"/>
    <inertia ixx="0.001068" iyy="0.001832" izz="0.002288" ixy="1.2e-05" iyz="-6e-06" ixz="0.000215"/>
  </inertial>
  <visual>
    <origin xyz="-0.012959 -0.110275 0.688357" rpy="0 0 0"/>
    <geometry>
      <mesh filename="package://ik_test/meshes/left_foot_1_1_1.stl" scale="0.001 0.001 0.001"/>
    </geometry>
    <material name="silver">
      <color rgba="0.700 0.700 0.700 1.000"/>
    </material>
  </visual>
  <collision>
    <geometry>
      <box size="0.2 0.13 0.012"/>
    </geometry>
    <origin xyz="0.025 0.0005 -0.071" rpy="0.0079 0 0"/>
  </collision>
</link>




<!-- <joint name="base_joint" type="prismatic">
  <origin xyz="0 0 0" rpy="0 0 0"/>
  <parent link="base_link"/>
  <child link="left_yaw_1_1_1"/>
  <axis xyz="0.0 0.0 1.0"/>
  <limit upper="0" lower="0" effort="100" velocity="1000"/>
</joint> -->

<joint name="base_joint" type="revolute">
  <parent link="world"/>
  <child link="base_link"/>
  <origin xyz="0 0 0" rpy="0 0 0"/>
  <axis xyz="0.0 0.0 1.0"/>
  <limit upper="1.570796" lower="-1.570796" effort="40" velocity="4.188790204786399"/>
</joint>

<joint name="hip_roll_left" type="revolute">
  <origin xyz="0.0 0.0 -0.096056" rpy="0 0 0"/>
  <parent link="base_link"/>
  <child link="left_hip_rp_1_1_1"/>
  <axis xyz="-1.0 0.0 0.0"/>
  <limit upper="1.570796" lower="-0.523599" effort="40" velocity="4.188790204786399"/>
</joint>

<joint name="hip_pitch_left" type="revolute">
  <origin xyz="0.02825 0.00175 0" rpy="0 0 0"/>
  <parent link="left_hip_rp_1_1_1"/>
  <child link="left_upper_link_1_1_1"/>
  <axis xyz="0.0 1.0 0"/>
  <limit upper="1.745329" lower="-0.471239" effort="65" velocity="5.236"/>
</joint>

<joint name="knee_left" type="revolute">
  <origin xyz="0.0 -0.003988 -0.3" rpy="0 0 0"/>
  <parent link="left_upper_link_1_1_1"/>
  <child link="left_lower_link_1_1_1"/>
  <axis xyz="0.0 -1.0 0"/>
  <limit upper="2.094395" lower="0.0" effort="65" velocity="5.236"/>
</joint>

<joint name="ankle_pitch_left" type="revolute">
  <origin xyz="0.0 0.000263 -0.3" rpy="0 0 0"/>
  <parent link="left_lower_link_1_1_1"/>
  <child link="left_ankle_1_1_1"/>
  <axis xyz="-0.0 1.0 0"/>
  <limit upper="1.047197551" lower="-0.785398" effort="8" velocity="41.88790204786399"/>
</joint>

<joint name="ankle_roll_left" type="revolute">
  <origin xyz="0.0 0.00125 0.0" rpy="0 0 0"/>
  <parent link="left_ankle_1_1_1"/>
  <child link="left_foot_1_1_1"/>
  <axis xyz="1.0 0.0 0.0"/>
  <limit upper="0.785398" lower="-0.785398" effort="8" velocity="41.88790204786399"/>
</joint>


<!-- <joint name="hip_roll_left" type="revolute">
  <origin xyz="-0.09875 0.0 -0.096056" rpy="0 0 0"/>
  <parent link="base_link"/>
  <child link="left_hip_rp_1_1_1"/>
  <axis xyz="1.0 0.0 -0.0"/>
  <limit upper="1.570796" lower="-0.523599" effort="40" velocity="4.188790204786399"/>
</joint>

<joint name="hip_pitch_left" type="revolute">
  <origin xyz="0.127 -0.039 -1e-06" rpy="0 0 0"/>
  <parent link="left_hip_rp_1_1_1"/>
  <child link="left_upper_link_1_1_1"/>
  <axis xyz="0.0 -1.0 -4.1e-05"/>
  <limit upper="1.745329" lower="-0.471239" effort="65" velocity="5.236"/>
</joint>

<joint name="knee_left" type="revolute">
  <origin xyz="0.0 -0.007488 -0.300001" rpy="0 0 0"/>
  <parent link="left_upper_link_1_1_1"/>
  <child link="left_lower_link_1_1_1"/>
  <axis xyz="-0.0 1.0 4.1e-05"/>
  <limit upper="2.094395" lower="0.0" effort="65" velocity="5.236"/>
</joint>

<joint name="ankle_pitch_left" type="revolute">
  <origin xyz="0.0 0.026013 -0.299999" rpy="0 0 0"/>
  <parent link="left_lower_link_1_1_1"/>
  <child link="left_ankle_1_1_1"/>
  <axis xyz="-0.0 -1.0 4.1e-05"/>
  <limit upper="1.047197551" lower="-0.785398" effort="8" velocity="41.88790204786399"/>
</joint>

<joint name="ankle_roll_left" type="revolute">
  <origin xyz="-0.049 0.02575 1e-06" rpy="0 0 0"/>
  <parent link="left_ankle_1_1_1"/>
  <child link="left_foot_1_1_1"/>
  <axis xyz="1.0 0.0 0.0"/>
  <limit upper="0.785398" lower="-0.785398" effort="8" velocity="41.88790204786399"/>
</joint> -->

</robot>
