<?xml version="1.0" ?>
<robot name="total_robot_nl" xmlns:xacro="http://www.ros.org/wiki/xacro">
<!-- 
<link name = "base_link">
  <inertial>
    <origin xyz="0 0 0" rpy="0 0 0"/>
    <mass value="0"/>
    <inertia ixx="0" iyy="0" izz="0" ixy="0" iyz="0" ixz="0"/>
  </inertial>
  <visual>
    <origin xyz="0 0 0" rpy="0 0 0"/>
    <geometry>
      <box size="0.01 0.01 0.01"/>
    </geometry>
  </visual>
</link> -->
<link name="world"/>
  
<link name="base_link">
  <inertial>
    <origin xyz="-0.0032551439887210324 -2.0000001658970756e-07 -0.04529738784398371" rpy="0 0 0"/>
    <mass value="0.6322493948525033"/>
    <inertia ixx="0.001017" iyy="0.004505" izz="0.003813" ixy="0.0" iyz="0.0" ixz="-0.000121"/>
  </inertial>
  <visual>
    <origin xyz="0.015291 0.105 -0.007699" rpy="0 0 0"/>
    <geometry>
      <mesh filename="package://ik_test/meshes/right_yaw_1_1_1.stl" scale="0.001 0.001 0.001"/>
    </geometry>
    <material name="silver">
      <color rgba="0.700 0.700 0.700 1.000"/>
    </material>
  </visual>
</link>

<link name="right_hip_rp_1_1_1">
  <inertial>
    <origin xyz="-0.000275128 0.0019294190715901938 9.221403702634745e-05" rpy="0 0 0"/>
    <!-- <origin xyz="0.09685174149735151 -0.0018821709981925172 9.35206557016871e-05" rpy="0 0 0"/> -->
    <mass value="3.5816786688919353"/>
    <inertia ixx="0.00491" iyy="0.013424" izz="0.012876" ixy="0.00022" iyz="-2.5e-05" ixz="-3.9e-05"/>
  </inertial>
  <visual>
    <!-- <origin xyz="0.114041 0.105 0.088357" rpy="0 0 0"/> -->
    <origin xyz="0.015291 0.105 0.088357" rpy="0 0 0"/>
    <geometry>
      <mesh filename="package://ik_test/meshes/right_hip_rp_1_1_1.stl" scale="0.001 0.001 0.001"/>
    </geometry>
    <material name="silver">
      <color rgba="0.700 0.700 0.700 1.000"/>
    </material>
  </visual>
</link>

<link name="right_upper_link_1_1_1">
  <inertial>
    <origin xyz="0.0005368519739045955 -0.013754235 -0.15022534580925995" rpy="0 0 0"/>
    <!-- <origin xyz="0.0005283462268753456 -0.035793629479377365 -0.15017576047478398" rpy="0 0 0"/> -->
    <mass value="3.224248608127142"/>
    <inertia ixx="0.017946" iyy="0.016983" izz="0.007545" ixy="2.3e-05" iyz="-0.000337" ixz="0.00025"/>
  </inertial>
  <visual>
    <!-- <origin xyz="-0.012959 0.066 0.088432" rpy="0 0 0"/> -->
    <origin xyz="-0.012959 0.11025 0.088358" rpy="0 0 0"/>
    <geometry>
      <mesh filename="package://ik_test/meshes/right_upper_link_1_1_1.stl" scale="0.001 0.001 0.001"/>
    </geometry>
    <material name="silver">
      <color rgba="0.700 0.700 0.700 1.000"/>
    </material>
  </visual>
</link>

<link name="right_lower_link_1_1_1">
  <inertial>
    <origin xyz="4.6165273849790855e-05 0.006328049 -0.07736569907214441" rpy="0 0 0"/>
    <!-- <origin xyz="4.616866161294246e-05 -0.054724321366379315 -0.07726279002046826" rpy="0 0 0"/> -->
    <mass value="2.1737761686430033"/>
    <inertia ixx="0.020231" iyy="0.0187" izz="0.003552" ixy="3e-06" iyz="-0.000588" ixz="-3.7e-05"/>
  </inertial>
  <visual>
    <!-- <origin xyz="-0.012959 0.05908 0.388446" rpy="0 0 0"/> -->
    <origin xyz="-0.012959 0.106762 0.388359" rpy="0 0 0"/>
    <geometry>
      <mesh filename="package://ik_test/meshes/right_lower_link_1_1_1.stl" scale="0.001 0.001 0.001"/>
    </geometry>
    <material name="silver">
      <color rgba="0.700 0.700 0.700 1.000"/>
    </material>
  </visual>
</link>

<link name="right_ankle_1_1_1">
  <inertial>
    <origin xyz="-5.379963106347946e-07 -0.000000102 2.7555327962835996e-05" rpy="0 0 0"/>
    <!-- <origin xyz="1.044337313665239e-06 -0.0257503951230489 7.565631622663549e-05" rpy="0 0 0"/> -->
    <mass value="0.09508659018482592"/>
    <inertia ixx="1.3e-05" iyy="6.1e-05" izz="6.9e-05" ixy="0.0" iyz="0.0" ixz="0.0"/>
  </inertial>
  <visual>
    <!-- <origin xyz="-0.012959 0.08566 0.688395" rpy="0 0 0"/> -->
    <origin xyz="-0.012959 0.110275 0.688358" rpy="0 0 0"/>
    <geometry>
      <mesh filename="package://ik_test/meshes/right_ankle_1_1_1.stl" scale="0.001 0.001 0.001"/>
    </geometry>
    <material name="silver">
      <color rgba="0.700 0.700 0.700 1.000"/>
    </material>
  </visual>
</link>

<link name="right_foot_1_1_1">
  <inertial>
    <origin xyz="0.005144916 -0.0011185339036274 -0.05368766786446966" rpy="0 0 0"/>
    <mass value="0.7656211376144055"/>
    <inertia ixx="0.001068" iyy="0.001832" izz="0.002289" ixy="-1.3e-05" iyz="4e-06" ixz="0.000216"/>
  </inertial>
  <visual>
    <!-- <origin xyz="0.036041 0.11141 0.688346" rpy="0 0 0"/> -->
    <origin xyz="-0.012959 0.110275 0.688357" rpy="0 0 0"/>
    <geometry>
      <mesh filename="package://ik_test/meshes/right_foot_1_1_1.stl" scale="0.001 0.001 0.001"/>
    </geometry>
    <material name="silver">
      <color rgba="0.700 0.700 0.700 1.000"/>
    </material>
  </visual>
</link>




<!-- <joint name="base_joint" type="prismatic">
  <origin xyz="0 0 0" rpy="0 0 0"/>
  <parent link="base_link"/>
  <child link="right_yaw_1_1_1"/>
  <axis xyz="0.0 0.0 1.0"/>
  <limit upper="0" lower="0" effort="100" velocity="1000"/>
</joint> -->

<joint name="base_joint" type="revolute">
  <parent link="world"/>
  <child link="base_link"/>
  <origin xyz="0 0 0" rpy="0 0 0"/>
  <axis xyz="0.0 0.0 1.0"/>
  <limit upper="1.570796" lower="-1.570796" effort="40" velocity="4.188790204786399"/>
</joint>

<joint name="hip_roll_right" type="revolute">
  <!-- <origin xyz="-0.09875 0.0 -0.096056" rpy="0 0 0"/> -->
  <origin xyz="0.0 0.0 -0.096056" rpy="0 0 0"/>
  <parent link="base_link"/>
  <child link="right_hip_rp_1_1_1"/>
  <axis xyz="-1.0 -0.0 0.0"/>
  <limit upper="1.570796" lower="-0.523599" effort="40" velocity="4.188790204786399"/>
</joint>

<joint name="hip_pitch_right" type="revolute">
  <!-- <origin xyz="0.127 0.039 -7.5e-05" rpy="0 0 0"/> -->
  <origin xyz="0.02825 0.00175 0" rpy="0 0 0"/>
  <parent link="right_hip_rp_1_1_1"/>
  <child link="right_upper_link_1_1_1"/>
  <axis xyz="0.0 -1.0 0"/>
  <limit upper="1.745329" lower="-0.471239" effort="65" velocity="5.236"/>
</joint>

<joint name="knee_right" type="revolute">
  <!-- <origin xyz="0.0 0.00692 -0.300014" rpy="0 0 0"/> -->
  <origin xyz="0.0 -0.003988 -0.3" rpy="0 0 0"/>
  <parent link="right_upper_link_1_1_1"/>
  <child link="right_lower_link_1_1_1"/>
  <axis xyz="0.0 1.0 0"/>
  <limit upper="2.094395" lower="0.0" effort="65" velocity="5.236"/>
</joint>

<joint name="ankle_pitch_right" type="revolute">
  <!-- <origin xyz="0.0 -0.02658 -0.299949" rpy="0 0 0"/> -->
  <!-- <origin xyz="0.0 0.000263 -0.3" rpy="0 0 0"/> -->
  <origin xyz="0.0 -0.003988 -0.3" rpy="0 0 0"/>
  <parent link="right_lower_link_1_1_1"/>
  <child link="right_ankle_1_1_1"/>
  <axis xyz="-0.0 1.0 0"/>
  <limit upper="1.047197551" lower="-0.785398" effort="8" velocity="41.88790204786399"/>
</joint>

<joint name="ankle_roll_right" type="revolute">
  <!-- <origin xyz="-0.049 -0.02575 4.9e-05" rpy="0 0 0"/> -->
  <origin xyz="0.0 0.00125 0.0" rpy="0 0 0"/>
  <parent link="right_ankle_1_1_1"/>
  <child link="right_foot_1_1_1"/>
  <axis xyz="1.0 0.0 0.0"/>
  <limit upper="0.785398" lower="-0.785398" effort="8" velocity="41.88790204786399"/>
</joint>


<!-- <joint name="hip_roll_right" type="revolute">
  <origin xyz="-0.09875 0.0 -0.096056" rpy="0 0 0"/>
  <parent link="base_link"/>
  <child link="right_hip_rp_1_1_1"/>
  <axis xyz="1.0 0.0 -0.0"/>
  <limit upper="1.570796" lower="-0.523599" effort="40" velocity="4.188790204786399"/>
</joint>

<joint name="hip_pitch_right" type="revolute">
  <origin xyz="0.127 -0.039 -1e-06" rpy="0 0 0"/>
  <parent link="right_hip_rp_1_1_1"/>
  <child link="right_upper_link_1_1_1"/>
  <axis xyz="0.0 -1.0 -4.1e-05"/>
  <limit upper="1.745329" lower="-0.471239" effort="65" velocity="5.236"/>
</joint>

<joint name="knee_right" type="revolute">
  <origin xyz="0.0 -0.007488 -0.300001" rpy="0 0 0"/>
  <parent link="right_upper_link_1_1_1"/>
  <child link="right_lower_link_1_1_1"/>
  <axis xyz="-0.0 1.0 4.1e-05"/>
  <limit upper="2.094395" lower="0.0" effort="65" velocity="5.236"/>
</joint>

<joint name="ankle_pitch_right" type="revolute">
  <origin xyz="0.0 0.026013 -0.299999" rpy="0 0 0"/>
  <parent link="right_lower_link_1_1_1"/>
  <child link="right_ankle_1_1_1"/>
  <axis xyz="-0.0 -1.0 4.1e-05"/>
  <limit upper="1.047197551" lower="-0.785398" effort="8" velocity="41.88790204786399"/>
</joint>

<joint name="ankle_roll_right" type="revolute">
  <origin xyz="-0.049 0.02575 1e-06" rpy="0 0 0"/>
  <parent link="right_ankle_1_1_1"/>
  <child link="right_foot_1_1_1"/>
  <axis xyz="1.0 0.0 0.0"/>
  <limit upper="0.785398" lower="-0.785398" effort="8" velocity="41.88790204786399"/>
</joint> -->

</robot>
