<?xml version="1.0" ?>
<mujoco model="robot_nl">
    <!-- <compiler angle="radian" meshdir="assets"/> -->
    <compiler angle="radian" meshdir="assets" autolimits="true"/>
    <default>
        <default class="robotnl">
        </default>
        <default class="hip_gains">
            <!-- <position kp="240" kv="5.0"/>  -->
        </default>
        <default class="hip_pitch_gains">
            <!-- <position kp="100" kv="2.5"/> -->
        </default>
        <default class="knee_gains">
            <!-- <position kp="15" kv="1.1"/> -->
        </default>
        <default class="ankle_gains">
            <!-- <position kp="10" kv="1.0"/> -->
        </default>

        <default class="visual">
            <geom type="mesh" contype="0" conaffinity="0" group="2"/>
        </default>
        <default class="collision">
            <geom group="3"/>
        </default>
    </default>

    <worldbody>
        <body name="base" pos="0 0 0.77" quat="1 0 0 0" childclass="robotnl">
            <freejoint name="base_freejoint"/>
            <!-- <camera name="robot_eye_view" pos="0 0.1 0.1" xyaxes="1 0 0 0 1 0" mode="fixed"/> -->
            <geom type="mesh" rgba="0.2 0.2 0.2 1" mesh="base_link" class="visual"/>
            <inertial pos="-0.00020305658642525651 -2.299524657931652e-06 0.1172286439789711" mass="5.152280783786209" fullinertia="0.047442 0.033846 0.037155 -0.0 0.000292 -1e-06" />
            <site group="3" name="imu" pos="0 0 0" quat="1 0 0 0"/>
            <body name="right_yaw" pos="-0.001536 -0.105 0.006958">
                <inertial pos="-0.003387170114723884 3.4379261523720395e-07 -0.044730635776334654" mass="0.23424145827439846" fullinertia="0.000378 0.001666 0.001409 0.0 -4.5e-05 0.0" />
                <joint name="hip_yaw_right" pos="0 0 0" axis="0 0 1" limited="true" range="-1.5708 0.698132" frictionloss="0.1" armature="0.005" />
                <geom pos="0.001536 0.105 -0.006958" type="mesh" rgba="0.85 0.85 0.85 1" mesh="right_yaw" class="visual"/>
                <body name="right_rp" pos="0 0 -0.095556">
                    <inertial pos="0.003062145 -0.002214028202584803 -6.154780610961863e-05" mass="0.690812556297437" fullinertia="0.00118 0.00287 0.00271 4.3e-05 -4e-06 -6e-06" /> 
                    <joint name="hip_roll_right" pos="0 0 0" axis="1 0 0" limited="true" range="-1.5708 0.872665" frictionloss="0.1" armature="0.005" />
                    <geom pos="0.001536 0.105 0.088598" type="mesh" rgba="0.65 0.65 0.65 1" mesh="right_rp" class="visual"/>
                    <body name="right_upper_link" pos="0.02795 0 -4.3e-05">
                        <inertial pos="0.002301542175954175 -0.002972894 -0.15079668153621606" mass="0.9258424873332725" fullinertia="0.006961 0.006745 0.002544 7e-06 0.000217 -0.000146" />
                        <joint name="hip_pitch_right" pos="0 0 0" axis="0 1 0" limited="true" range="-1.8326 0.523599" frictionloss="0.1" armature="0.005" />
                        <geom pos="-0.026414 0.105 0.088641" type="mesh" rgba="0.65 0.65 0.65 1" mesh="right_upper_link" class="visual"/>
                        <body name="right_lower_link" pos="0 -0.005288 -0.3">
                            <inertial pos="0.001498001214367918 -0.002773083 -0.08163965093235381" mass="0.6817251658718579" fullinertia="0.007024 0.006492 0.001195 -0.0 -5.2e-05 -4.5e-05" />
                            <joint name="knee_right" pos="0 0 0" axis="0 1 0" limited="true" range="0 2.1293" frictionloss="0.1" armature="0.005" />
                            <geom pos="-0.026414 0.110288 0.388641" type="mesh" rgba="0.85 0.85 0.85 1" mesh="right_lower_link" class="visual"/>
                            <body name="right_ankle" pos="0 0.000561 -0.299939">
                                <inertial pos="4.824912801307257e-07 -0.000000367 3.398427368073165e-05" mass="0.03255793420333914" fullinertia="5e-06 1.7e-05 2e-05 0.0 0.0 0.0" />
                                <joint name="ankle_pitch_right" pos="0 0 0" axis="0 1 0" limited="true" range="-1.22173 1.0472" frictionloss="0.1" armature="0.005" />
                                <geom pos="-0.026414 0.109727 0.68858" type="mesh" rgba="0.85 0.85 0.85 1" mesh="right_ankle" class="visual"/>
                                <body name="right_foot" pos="0 0 -2.2e-05">
                                    <inertial pos="0.01761519535511249 -0.0005768277267058086 -0.0580822077884815" mass="0.4255598361250292" fullinertia="0.000686 0.001174 0.001512 -8e-06 3.2e-05 2e-06" />
                                    <joint name="ankle_roll_right" pos="0 0 0" axis="1 0 0" limited="true" range="-0.523599 0.663225" frictionloss="0.1" armature="0.005" />
                                    <geom pos="-0.026414 0.109727 0.688602" type="mesh" rgba="0.2 0.2 0.2 1" mesh="right_foot" class="visual"/>
                                    <geom class="collision" type="box" pos="0.0265 -0.00035 -0.071" quat="1 0 0 0" size="0.1 0.065 0.0065" friction="1.0 0.005 0.0001"/>
                                </body>
                            </body>
                        </body>
                    </body>
                </body>
            </body>
            <body name="left_yaw" pos="-0.001536 0.105 0.006958">
                <inertial pos="-0.003387170113489349 3.437926530541757e-07 -0.04472797689299879" mass="0.23424145827233966" fullinertia="0.000378 0.001666 0.001409 0.0 -4.5e-05 0.0" />
                <joint name="hip_yaw_left" pos="0 0 0" axis="0 0 1" limited="true" range="-0.698132 1.5708" frictionloss="0.1" armature="0.005" />
                <geom pos="0.001536 -0.105 -0.006958" type="mesh" rgba="0.85 0.85 0.85 1" mesh="left_yaw" class="visual"/>
                <body name="left_rp" pos="0 0 -0.095556">
                    <inertial pos="0.003062159 0.002214840752492689 -5.654296421113425e-05" mass="0.6908122901011517" fullinertia="0.00118 0.002869 0.00271 -4.3e-05 -4e-06 7e-06" />
                    <joint name="hip_roll_left" pos="0 0 0" axis="1 0 0" limited="true" range="-0.698132 1.5708" frictionloss="0.1" armature="0.005" />
                    <geom pos="0.001536 -0.105 0.088598" type="mesh" rgba="0.65 0.65 0.65 1" mesh="left_rp" class="visual"/>
                    <body name="left_upper_link" pos="0.02795 0 6.9e-05">
                        <inertial pos="0.0023146429745539224 0.003311485 -0.1508794685104973" mass="0.9255380783714433" fullinertia="0.006959 0.006742 0.002543 -8e-06 0.000218 0.000155" />
                        <joint name="hip_pitch_left" pos="0 0 0" axis="0 1 0" limited="true" range="-1.8326 0.523599" frictionloss="0.1" armature="0.005" />
                        <geom pos="-0.026414 -0.105 0.088529" type="mesh" rgba="0.65 0.65 0.65 1" mesh="left_upper_link" class="visual"/>
                        <body name="left_lower_link" pos="0 0.005969 -0.299988">
                            <inertial pos="0.0014979772223235738 0.00325822 -0.08174396151435326" mass="0.6817257546564137" fullinertia="0.007024 0.006492 0.001195 0.0 -5.2e-05 5.7e-05" />
                            <joint name="knee_left" pos="0 0 0" axis="0 1 0" limited="true" range="0 2.1293" frictionloss="0.1" armature="0.005" />
                            <geom pos="-0.026414 -0.110969 0.388517" type="mesh" rgba="0.85 0.85 0.85 1" mesh="left_lower_link" class="visual"/>
                            <body name="left_ankle" pos="0 0.000419 -0.300036">
                                <inertial pos="-1.2225763775797205e-06 0.000000402 1.968676151820059e-05" mass="0.032557947198084525" fullinertia="5e-06 1.7e-05 2e-05 0.0 0.0 0.0" />
                                <joint name="ankle_pitch_left" pos="0 0 0" axis="0 1 0" limited="true" range="-1.22173 1.0472" frictionloss="0.1" armature="0.005" />
                                <geom pos="-0.026414 -0.111388 0.688553" type="mesh" rgba="0.85 0.85 0.85 1" mesh="left_ankle" class="visual"/>
                                <body name="left_foot" pos="0 0 -3.6e-05">
                                    <inertial pos="0.02701606411021572 0.0006641852928514075 -0.058081445541025456" mass="0.42555979909734665" fullinertia="0.000686 0.001174 0.001512 8e-06 -2e-06 3.2e-05" />
                                    <joint name="ankle_roll_left" pos="0 0 0" axis="1 0 0" limited="true" range="-0.663225 0.523599" frictionloss="0.1" armature="0.005" />
                                    <geom pos="-0.031414 -0.111388 0.688589" type="mesh" rgba="0.2 0.2 0.2 1" mesh="left_foot" class="visual"/>
                                    <geom class="collision" type="box" pos="0.0265 0.0005 -0.071" quat="1 0 0 0" size="0.1 0.065 0.0065" friction="1.0 0.005 0.0001"/>
                                </body>
                            </body>
                        </body>
                    </body>
                </body>
            </body>
        </body>
    </worldbody>

    <asset>
        <mesh name="base_link"          file="robotnl_meshes/base_link.stl"            scale="0.001 0.001 0.001" />
        <mesh name="right_yaw"          file="robotnl_meshes/right_yaw.stl"            scale="0.001 0.001 0.001" />
        <mesh name="right_rp"           file="robotnl_meshes/right_rp.stl"             scale="0.001 0.001 0.001" />
        <mesh name="right_upper_link"   file="robotnl_meshes/right_upper_link.stl"     scale="0.001 0.001 0.001" />
        <mesh name="right_lower_link"   file="robotnl_meshes/right_lower_link.stl"     scale="0.001 0.001 0.001" />
        <mesh name="right_ankle"        file="robotnl_meshes/right_ankle.stl"          scale="0.001 0.001 0.001" />
        <mesh name="right_foot"         file="robotnl_meshes/right_foot.stl"           scale="0.001 0.001 0.001" />
        <mesh name="left_yaw"           file="robotnl_meshes/left_yaw.stl"             scale="0.001 0.001 0.001" />
        <mesh name="left_rp"            file="robotnl_meshes/left_rp.stl"              scale="0.001 0.001 0.001" />
        <mesh name="left_upper_link"    file="robotnl_meshes/left_upper_link.stl"      scale="0.001 0.001 0.001" />
        <mesh name="left_lower_link"    file="robotnl_meshes/left_lower_link.stl"      scale="0.001 0.001 0.001" />
        <mesh name="left_ankle"         file="robotnl_meshes/left_ankle.stl"           scale="0.001 0.001 0.001" />
        <mesh name="left_foot"          file="robotnl_meshes/left_foot.stl"            scale="0.001 0.001 0.001" />
    </asset>

    <actuator>
        <motor class="hip_gains"        name="hip_yaw_left"          joint="hip_yaw_left"          forcerange="-30 30"/>
        <motor class="hip_gains"        name="hip_yaw_right"         joint="hip_yaw_right"         forcerange="-30 30"/>
        <motor class="hip_gains"        name="hip_roll_left"         joint="hip_roll_left"         forcerange="-30 30"/>
        <motor class="hip_gains"        name="hip_roll_right"        joint="hip_roll_right"        forcerange="-30 30"/>
        <motor class="hip_pitch_gains"  name="hip_pitch_left"        joint="hip_pitch_left"        forcerange="-50 50"/>
        <motor class="hip_pitch_gains"  name="hip_pitch_right"       joint="hip_pitch_right"       forcerange="-50 50"/>
        <motor class="knee_gains"       name="knee_left"             joint="knee_left"             forcerange="-50 50"/>
        <motor class="knee_gains"       name="knee_right"            joint="knee_right"            forcerange="-50 50"/>
        <motor class="ankle_gains"      name="ankle_pitch_left"      joint="ankle_pitch_left"      forcerange="-6  6 "/>
        <motor class="ankle_gains"      name="ankle_pitch_right"     joint="ankle_pitch_right"     forcerange="-6  6 "/>
        <motor class="ankle_gains"      name="ankle_roll_left"       joint="ankle_roll_left"       forcerange="-6  6 "/>
        <motor class="ankle_gains"      name="ankle_roll_right"      joint="ankle_roll_right"      forcerange="-6  6 "/>
    </actuator>

    <!-- <actuator>
        <motor class="hip_gains"        name="hip_yaw_left"          joint="hip_yaw_left"          forcerange="-30 30"/>
        <motor class="hip_gains"        name="hip_roll_left"         joint="hip_roll_left"         forcerange="-30 30"/>
        <motor class="hip_pitch_gains"  name="hip_pitch_left"        joint="hip_pitch_left"        forcerange="-50 50"/>
        <motor class="knee_gains"       name="knee_left"             joint="knee_left"             forcerange="-50 50"/>
        <motor class="ankle_gains"      name="ankle_pitch_left"      joint="ankle_pitch_left"      forcerange="-6  6 "/>
        <motor class="ankle_gains"      name="ankle_roll_left"       joint="ankle_roll_left"       forcerange="-6  6 "/>
        <motor class="hip_gains"        name="hip_yaw_right"         joint="hip_yaw_right"         forcerange="-30 30"/>
        <motor class="hip_gains"        name="hip_roll_right"        joint="hip_roll_right"        forcerange="-30 30"/>
        <motor class="hip_pitch_gains"  name="hip_pitch_right"       joint="hip_pitch_right"       forcerange="-50 50"/>
        <motor class="knee_gains"       name="knee_right"            joint="knee_right"            forcerange="-50 50"/>
        <motor class="ankle_gains"      name="ankle_pitch_right"     joint="ankle_pitch_right"     forcerange="-6  6 "/>
        <motor class="ankle_gains"      name="ankle_roll_right"      joint="ankle_roll_right"      forcerange="-6  6 "/>
    </actuator> -->

    <sensor>
        <!-- <jointpos name="hip_yaw_left_pos"          joint="hip_yaw_left"       />
        <jointpos name="hip_roll_left_pos"         joint="hip_roll_left"      />
        <jointpos name="hip_pitch_left_pos"        joint="hip_pitch_left"     />
        <jointpos name="knee_left_pos"             joint="knee_left"          />
        <jointpos name="ankle_pitch_left_pos"      joint="ankle_pitch_left"   />
        <jointpos name="ankle_roll_left_pos"       joint="ankle_roll_left"    />
        <jointpos name="hip_yaw_right_pos"         joint="hip_yaw_right"      />
        <jointpos name="hip_roll_right_pos"        joint="hip_roll_right"     />
        <jointpos name="hip_pitch_right_pos"       joint="hip_pitch_right"    />
        <jointpos name="knee_right_pos"            joint="knee_right"         />
        <jointpos name="ankle_pitch_right_pos"     joint="ankle_pitch_right"  />
        <jointpos name="ankle_roll_right_pos"      joint="ankle_roll_right"   />

        <jointvel name="hip_yaw_left_vel"          joint="hip_yaw_left"       />
        <jointvel name="hip_roll_left_vel"         joint="hip_roll_left"      />
        <jointvel name="hip_pitch_left_vel"        joint="hip_pitch_left"     />
        <jointvel name="knee_left_vel"             joint="knee_left"          />
        <jointvel name="ankle_pitch_left_vel"      joint="ankle_pitch_left"   />
        <jointvel name="ankle_roll_left_vel"       joint="ankle_roll_left"    />
        <jointvel name="hip_yaw_right_vel"         joint="hip_yaw_right"      />
        <jointvel name="hip_roll_right_vel"        joint="hip_roll_right"     />
        <jointvel name="hip_pitch_right_vel"       joint="hip_pitch_right"    />
        <jointvel name="knee_right_vel"            joint="knee_right"         />
        <jointvel name="ankle_pitch_right_vel"     joint="ankle_pitch_right"  />
        <jointvel name="ankle_roll_right_vel"      joint="ankle_roll_right"   />

        <jointactuatorfrc name="hip_yaw_left_torque"          joint="hip_yaw_left"       />
        <jointactuatorfrc name="hip_roll_left_torque"         joint="hip_roll_left"      />
        <jointactuatorfrc name="hip_pitch_left_torque"        joint="hip_pitch_left"     />
        <jointactuatorfrc name="knee_left_torque"             joint="knee_left"          />
        <jointactuatorfrc name="ankle_pitch_left_torque"      joint="ankle_pitch_left"   />
        <jointactuatorfrc name="ankle_roll_left_torque"       joint="ankle_roll_left"    />
        <jointactuatorfrc name="hip_yaw_right_torque"         joint="hip_yaw_right"      />
        <jointactuatorfrc name="hip_roll_right_torque"        joint="hip_roll_right"     />
        <jointactuatorfrc name="hip_pitch_right_torque"       joint="hip_pitch_right"    />
        <jointactuatorfrc name="knee_right_torque"            joint="knee_right"         />
        <jointactuatorfrc name="ankle_pitch_right_torque"     joint="ankle_pitch_right"  />
        <jointactuatorfrc name="ankle_roll_right_torque"      joint="ankle_roll_right"   /> -->

        <jointpos name="hip_yaw_left_pos"          joint="hip_yaw_left"       />
        <jointpos name="hip_yaw_right_pos"         joint="hip_yaw_right"      />
        <jointpos name="hip_roll_left_pos"         joint="hip_roll_left"      />
        <jointpos name="hip_roll_right_pos"        joint="hip_roll_right"     />
        <jointpos name="hip_pitch_left_pos"        joint="hip_pitch_left"     />
        <jointpos name="hip_pitch_right_pos"       joint="hip_pitch_right"    />
        <jointpos name="knee_left_pos"             joint="knee_left"          />
        <jointpos name="knee_right_pos"            joint="knee_right"         />
        <jointpos name="ankle_pitch_left_pos"      joint="ankle_pitch_left"   />
        <jointpos name="ankle_pitch_right_pos"     joint="ankle_pitch_right"  />
        <jointpos name="ankle_roll_left_pos"       joint="ankle_roll_left"    />
        <jointpos name="ankle_roll_right_pos"      joint="ankle_roll_right"   />
        

        <jointvel name="hip_yaw_left_vel"          joint="hip_yaw_left"       />
        <jointvel name="hip_yaw_right_vel"         joint="hip_yaw_right"      />
        <jointvel name="hip_roll_left_vel"         joint="hip_roll_left"      />
        <jointvel name="hip_roll_right_vel"        joint="hip_roll_right"     />
        <jointvel name="hip_pitch_left_vel"        joint="hip_pitch_left"     />
        <jointvel name="hip_pitch_right_vel"       joint="hip_pitch_right"    />
        <jointvel name="knee_left_vel"             joint="knee_left"          />
        <jointvel name="knee_right_vel"            joint="knee_right"         />
        <jointvel name="ankle_pitch_left_vel"      joint="ankle_pitch_left"   />
        <jointvel name="ankle_pitch_right_vel"     joint="ankle_pitch_right"  />
        <jointvel name="ankle_roll_left_vel"       joint="ankle_roll_left"    />
        <jointvel name="ankle_roll_right_vel"      joint="ankle_roll_right"   />
        

        <jointactuatorfrc name="hip_yaw_left_torque"          joint="hip_yaw_left"       />
        <jointactuatorfrc name="hip_yaw_right_torque"         joint="hip_yaw_right"      />
        <jointactuatorfrc name="hip_roll_left_torque"         joint="hip_roll_left"      />
        <jointactuatorfrc name="hip_roll_right_torque"        joint="hip_roll_right"     />
        <jointactuatorfrc name="hip_pitch_left_torque"        joint="hip_pitch_left"     />
        <jointactuatorfrc name="hip_pitch_right_torque"       joint="hip_pitch_right"    />
        <jointactuatorfrc name="knee_left_torque"             joint="knee_left"          />
        <jointactuatorfrc name="knee_right_torque"            joint="knee_right"         />
        <jointactuatorfrc name="ankle_pitch_left_torque"      joint="ankle_pitch_left"   />
        <jointactuatorfrc name="ankle_pitch_right_torque"     joint="ankle_pitch_right"  />
        <jointactuatorfrc name="ankle_roll_left_torque"       joint="ankle_roll_left"    />
        <jointactuatorfrc name="ankle_roll_right_torque"      joint="ankle_roll_right"   />


        <framequat name="imu_quat" objtype="site" objname="imu" />
        <gyro name="imu_gyro" site="imu" />
        <accelerometer name="imu_acc" site="imu" />
        <framepos name="frame_pos" objtype="site" objname="imu" />
        <framelinvel name="frame_vel" objtype="site" objname="imu" />
    </sensor>
    <equality/>



    <statistic center="0 0 0.1" extent="0.8"/>
    <visual>
        <headlight diffuse="0.6 0.6 0.6" ambient="0.3 0.3 0.3" specular="0 0 0"/>
        <rgba haze="0.15 0.25 0.35 1"/>
        <global azimuth="120" elevation="-20"/>
    </visual>
    <asset>
        <texture type="skybox" builtin="gradient" rgb1="0.3 0.5 0.7" rgb2="0 0 0" width="512" height="3072"/>
        <texture type="2d" name="groundplane" builtin="checker" mark="edge" rgb1="0.2 0.3 0.4" rgb2="0.1 0.2 0.3"
        markrgb="0.8 0.8 0.8" width="300" height="300"/>
        <material name="groundplane" texture="groundplane" texuniform="true" texrepeat="5 5" reflectance="0.2"/>
    </asset>
    <worldbody>
        <light pos="0 0 1.5" dir="0 0 -1" directional="true"/>
        <geom name="floor" size="0 0 0.05" type="plane" material="groundplane" friction="1.0 0.005 0.0001"/>
    </worldbody>
</mujoco>
